Workbook

Sheet 📊 Dashboard
B2: KELOMPOK SUNCOST — KALKULATOR PLTS ATAP
B4: Sprint Tracker · Junior Project · Teknik Basis Data & Pemrograman Berbasis Objek
B6: PROJECT INFO | G6: LIVE KPI
B7: Project Name | C7: SunCost — kalkulator kelayakan investasi PLTS atap | G7: Total Tasks | I7: Completed | K7: In Progress | M7: Blocked
B8: Period | C8: 7 September — 11 Oktober 2026 (5 weeks) | G8: =COUNTA('📋 Task Tracker'!$D$11:$D$212) | I8: =COUNTIF('📋 Task Tracker'!$I$11:$I$212,"Done") | K8: =COUNTIF('📋 Task Tracker'!$I$11:$I$212,"In Progress") | M8: =COUNTIF('📋 Task Tracker'!$I$11:$I$212,"Blocked")
B9: Team Size | C9: 3
B10: Kategori | C10: Climate Action — energi terbarukan
B11: Architecture | C11: Desktop MVVM — C# WPF (.NET 8) + SQLite lokal + API Open-Meteo | G11: OVERALL COMPLETION
B12: Repository | C12: https://github.com/Yeypayeyy/22_SunCost | G12: =IFERROR(COUNTIF('📋 Task Tracker'!$I$11:$I$212,"Done")/COUNTA('📋 Task Tracker'!$D$11:$D$212),0)
B13: Mockup UI | C13: https://www.figma.com/design/eZ7u3wVkggATG2xYOc4SmW/
B14: Metode inti | C14: Energi tahunan = kWp × PSH × PR × 365, koreksi suhu 0,4%/°C
B16: SPRINT OVERVIEW
B18: SPRINT 1 | D18: SPRINT 2 | F18: SPRINT 3 | H18: SPRINT 4 | J18: SPRINT 5
B19: 1 — 13 Sep | D19: 14 — 20 Sep | F19: 21 — 27 Sep | H19: 28 Sep — 4 Okt | J19: 5 — 11 Okt | L19: <- ikuti jadwal asistensi lab
B20: FONDASI | D20: KALKULATOR | F20: HASIL | H20: BASIS DATA | J20: POLES & DEMO
B21: Repo, project WPF, design system, skema DB | D21: API cuaca + mesin perhitungan energi | F21: Finansial, lingkungan, visualisasi | H21: SQLite, riwayat, banding skenario | J21: Bug fix, dokumentasi, demo
B23: =IFERROR(COUNTIFS('📋 Task Tracker'!$G$11:$G$212,"Sprint 1",'📋 Task Tracker'!$I$11:$I$212,"Done")/COUNTIF('📋 Task Tracker'!$G$11:$G$212,"Sprint 1"),0) | D23: =IFERROR(COUNTIFS('📋 Task Tracker'!$G$11:$G$212,"Sprint 2",'📋 Task Tracker'!$I$11:$I$212,"Done")/COUNTIF('📋 Task Tracker'!$G$11:$G$212,"Sprint 2"),0) | F23: =IFERROR(COUNTIFS('📋 Task Tracker'!$G$11:$G$212,"Sprint 3",'📋 Task Tracker'!$I$11:$I$212,"Done")/COUNTIF('📋 Task Tracker'!$G$11:$G$212,"Sprint 3"),0) | H23: =IFERROR(COUNTIFS('📋 Task Tracker'!$G$11:$G$212,"Sprint 4",'📋 Task Tracker'!$I$11:$I$212,"Done")/COUNTIF('📋 Task Tracker'!$G$11:$G$212,"Sprint 4"),0) | J23: =IFERROR(COUNTIFS('📋 Task Tracker'!$G$11:$G$212,"Sprint 5",'📋 Task Tracker'!$I$11:$I$212,"Done")/COUNTIF('📋 Task Tracker'!$G$11:$G$212,"Sprint 5"),0)
B26: STATUS LEGEND
B28: Not Started | D28: In Progress | F28: In Review | H28: Done | J28: Blocked | L28: Cancelled
B30: QUICK NOTES & ANNOUNCEMENTS
B31: • Tracking cukup di spreadsheet ini, tidak pakai tool lain. • S2.3 (rumus energi) dan S4.1 (SQLite) dependensi kritis — telat di sini menggeser sprint berikutnya. • Hasil perhitungan wajib diuji silang ke PVGIS sebelum masuk sprint 3. • Risiko terbesar: aplikasi tidak jalan di laptop lain saat demo — diuji di S5.4, jangan ditunda.

Sheet 🎓 Assessment Tracker
B2: ASSESSMENT TRACKER
B4: Kriteria penilaian junior project · self-assessment tiap sprint · diisi setelah asistensi
B6: SCORING RUBRIC (Total = 100%)
B7: Criteria | C7: Weight | D7: Description
B8: Perancangan & Arsitektur | C8: 20% | D8: Class diagram, use case, ERD, pemisahan Model/Service/View jelas
B9: Implementasi OOP | C9: 25% | D9: Enkapsulasi, inheritance, interface, MVVM dan data binding dipakai benar
B10: Basis Data | C10: 20% | D10: Skema ternormalisasi, query agregasi/filter, akses data rapi lewat repository
B11: Akurasi Perhitungan | C11: 15% | D11: Hasil energi & finansial tervalidasi terhadap PVGIS, asumsi ditampilkan terbuka
B12: Dokumentasi | C12: 10% | D12: README, ERD, diagram, sumber data dan tarif tercatat
B13: Demo & Presentasi | C13: 10% | D13: Aplikasi jalan di laptop lain, demo terstruktur, tanya jawab lancar
B16: TEAM SELF-ASSESSMENT — Track our own progress against rubric
B17: Criteria | C17: Weight | D17: Sprint 1 | E17: Sprint 2 | F17: Sprint 3 | G17: Sprint 4 | H17: Sprint 5 | I17: Final Score | J17: Weighted | K17: Notes
B18: Perancangan & Arsitektur | C18: 0.2 | I18: =IFERROR(AVERAGE(D18:H18),0) | J18: =I18*C18
B19: Implementasi OOP | C19: 0.25 | I19: =IFERROR(AVERAGE(D19:H19),0) | J19: =I19*C19
B20: Basis Data | C20: 0.2 | I20: =IFERROR(AVERAGE(D20:H20),0) | J20: =I20*C20
B21: Akurasi Perhitungan | C21: 0.15 | I21: =IFERROR(AVERAGE(D21:H21),0) | J21: =I21*C21
B22: Dokumentasi | C22: 0.1 | I22: =IFERROR(AVERAGE(D22:H22),0) | J22: =I22*C22
B23: Demo & Presentasi | C23: 0.1 | I23: =IFERROR(AVERAGE(D23:H23),0) | J23: =I23*C23
B24: TOTAL | C24: =SUM(C18:C23) | I24: FINAL | J24: =SUM(J18:J23)
B26: LOG ASISTENSI & REVIEW
B27: # | C27: Tanggal | D27: Sprint | E27: Topik / Yang dibahas | G27: Catatan asisten | H27: Tindak lanjut | J27: PIC | K27: Deadline | L27: Status
B28: 1
B29: 2
B30: 3
B31: 4
B32: 5
B33: 6
B34: 7
B35: 8

Sheet 📋 Task Tracker
B2: TASK TRACKER
B4: Backlog rinci · perbarui kolom STATUS untuk melacak progres · filter per Sprint atau PIC
B6: Total | D6: Done | F6: In Progress | H6: Blocked | J6: Not Started | L6: % Complete
B7: =COUNTA(D11:D212) | D7: =COUNTIF(I11:I212,"Done") | F7: =COUNTIF(I11:I212,"In Progress") | H7: =COUNTIF(I11:I212,"Blocked") | J7: =COUNTIF(I11:I212,"Not Started") | L7: =IFERROR(COUNTIF(I11:I212,"Done")/COUNTA(D11:D212),0)
B10: # | C10: Sprint Goal | D10: Task ID | E10: Task Description | F10: PIC | G10: Sprint | H10: Priority | I10: Status | J10: Start Date | K10: DEADLINE | L10: Sisa Hari | M10: Notes / Blockers
B11: 1 | C11: S1 — Fondasi | D11: S1.1 | E11: Finalisasi worksheet brainstorming + README project | F11: Farrel - Arch & UI | G11: Sprint 1 | H11: High | I11: Done | J11: 46272 | K11: 46273 | L11: =IF(K11="","",K11-TODAY()) | M11: Sudah di-merge lewat PR #6
B12: 2 | C12: S1 — Fondasi | D12: S1.2 | E12: Setup repo GitHub + branching per anggota | F12: Farrel - Arch & UI | G12: Sprint 1 | H12: High | I12: Done | J12: 46272 | K12: 46273 | L12: =IF(K12="","",K12-TODAY()) | M12: Branch 540589 / 538308 / 521971 | O12: Fitur/use case Utama Sprint 1: user bisa upload dokumen, staff/panitia bisa ngeapprove/unapprove dokumennya, user bisa liat status approvalnya
B13: 3 | C13: S1 — Fondasi | D13: S1.3 | E13: Buat project WPF .NET 8 + struktur folder (Models/Views) | F13: Farrel - Arch & UI | G13: Sprint 1 | H13: High | I13: Done | J13: 46273 | K13: 46274 | L13: =IF(K13="","",K13-TODAY()) | M13: Belum di-build, SDK belum terpasang
B14: 4 | C14: S1 — Fondasi | D14: S1.4 | E14: Design system: token warna + style Card/Button/Nav di App.xaml | F14: Farrel - Arch & UI | G14: Sprint 1 | H14: High | I14: Done | J14: 46273 | K14: 46274 | L14: =IF(K14="","",K14-TODAY())
B15: 5 | C15: S1 — Fondasi | D15: S1.5 | E15: Mockup UI 5 layar di Figma | F15: Farrel - Arch & UI | G15: Sprint 1 | H15: High | I15: Done | J15: 46273 | K15: 46275 | L15: =IF(K15="","",K15-TODAY()) | M15: Beranda, Input, Hasil x2, Riwayat
B16: 6 | C16: S1 — Fondasi | D16: S1.6 | E16: Rancang skema SQLite: tabel simulasi, panel, tarif_listrik | F16: Sri - Backend | G16: Sprint 1 | H16: High | I16: Not Started | J16: 46274 | K16: 46276 | L16: =IF(K16="","",K16-TODAY())
B17: 7 | C17: S1 — Fondasi | D17: S1.7 | E17: Class diagram + use case diagram (draw.io) | F17: Farrel - Arch & UI | G17: Sprint 1 | H17: Medium | I17: In Progress | J17: 46274 | K17: 46276 | L17: =IF(K17="","",K17-TODAY()) | M17: Draf .drawio sudah ada, perlu disesuaikan
B18: 8 | C18: S1 — Fondasi | D18: S1.8 | E18: Implementasi halaman Beranda (shell + sidebar + kartu riwayat) | F18: Mayra - Frontend | G18: Sprint 1 | H18: High | I18: In Progress | J18: 46275 | K18: 46278 | L18: =IF(K18="","",K18-TODAY()) | M18: Kode sudah ditulis, menunggu build
B19: 9 | C19: S2 — Kalkulator | D19: S2.1 | E19: Service Open-Meteo: radiasi harian + suhu rata-rata per koordinat | F19: Sri - Backend | G19: Sprint 2 | H19: High | I19: Not Started | J19: 46279 | K19: 46281 | L19: =IF(K19="","",K19-TODAY()) | M19: HttpClient + System.Text.Json
B20: 10 | C20: S2 — Kalkulator | D20: S2.2 | E20: Hitung kapasitas terpasang (kWp) dari luas atap, orientasi, kemiringan | F20: Sri - Backend | G20: Sprint 2 | H20: High | I20: Not Started | J20: 46279 | K20: 46281 | L20: =IF(K20="","",K20-TODAY())
B21: 11 | C21: S2 — Kalkulator | D21: S2.3 | E21: Rumus energi tahunan kWp x PSH x PR x 365 + koreksi suhu 0,4% per °C | F21: Sri - Backend | G21: Sprint 2 | H21: High | I21: Not Started | J21: 46281 | K21: 46283 | L21: =IF(K21="","",K21-TODAY()) | M21: Inti perhitungan — wajib ada unit test
B22: 12 | C22: S2 — Kalkulator | D22: S2.4 | E22: Halaman Input Simulasi: form, dropdown orientasi, slider kemiringan | F22: Mayra - Frontend | G22: Sprint 2 | H22: High | I22: Not Started | J22: 46279 | K22: 46283 | L22: =IF(K22="","",K22-TODAY())
B23: 13 | C23: S2 — Kalkulator | D23: S2.5 | E23: INotifyPropertyChanged supaya preview kWp update saat form diketik | F23: Mayra - Frontend | G23: Sprint 2 | H23: High | I23: Not Started | J23: 46282 | K23: 46284 | L23: =IF(K23="","",K23-TODAY()) | M23: Titik masuk pola MVVM
B24: 14 | C24: S2 — Kalkulator | D24: S2.6 | E24: Data golongan tarif PLN (R-1 900VA s.d. R-3) + opsi tarif manual | F24: Sri - Backend | G24: Sprint 2 | H24: Medium | I24: Not Started | J24: 46281 | K24: 46283 | L24: =IF(K24="","",K24-TODAY()) | M24: Sumber tarif harus dicatat
B25: 15 | C25: S2 — Kalkulator | D25: S2.7 | E25: Review arsitektur: pemisahan Service / Model / View sudah bersih? | F25: Farrel - Arch & UI | G25: Sprint 2 | H25: Medium | I25: Not Started | J25: 46284 | K25: 46285 | L25: =IF(K25="","",K25-TODAY())
B26: 16 | C26: S2 — Kalkulator | D26: S2.8 | E26: Uji silang 3 skenario input terhadap PVGIS untuk validasi hasil | F26: Farrel - Arch & UI | G26: Sprint 2 | H26: High | I26: Not Started | J26: 46284 | K26: 46285 | L26: =IF(K26="","",K26-TODAY()) | M26: Bukti bahwa perhitungan tidak asal
B27: 17 | C27: S3 — Hasil | D27: S3.1 | E27: Halaman Hasil Energi: KPI + bar chart produksi 12 bulan | F27: Mayra - Frontend | G27: Sprint 3 | H27: High | I27: Not Started | J27: 46286 | K27: 46289 | L27: =IF(K27="","",K27-TODAY()) | M27: ItemsControl + Rectangle, tanpa library
B28: 18 | C28: S3 — Hasil | D28: S3.2 | E28: Panel asumsi perhitungan terbuka (PSH, PR, koreksi suhu, degradasi) | F28: Mayra - Frontend | G28: Sprint 3 | H28: High | I28: Not Started | J28: 46287 | K28: 46289 | L28: =IF(K28="","",K28-TODAY()) | M28: Pembeda utama produk
B29: 19 | C29: S3 — Hasil | D29: S3.3 | E29: Perhitungan finansial: biaya instalasi, hemat/bulan, periode balik modal | F29: Sri - Backend | G29: Sprint 3 | H29: High | I29: Not Started | J29: 46286 | K29: 46289 | L29: =IF(K29="","",K29-TODAY())
B30: 20 | C30: S3 — Hasil | D30: S3.4 | E30: Proyeksi arus kas kumulatif 25 tahun + degradasi panel 0,5% per tahun | F30: Sri - Backend | G30: Sprint 3 | H30: High | I30: Not Started | J30: 46288 | K30: 46290 | L30: =IF(K30="","",K30-TODAY())
B31: 21 | C31: S3 — Hasil | D31: S3.5 | E31: Halaman Hasil Finansial: kartu KPI + line chart Polyline | F31: Mayra - Frontend | G31: Sprint 3 | H31: High | I31: Not Started | J31: 46289 | K31: 46292 | L31: =IF(K31="","",K31-TODAY())
B32: 22 | C32: S3 — Hasil | D32: S3.6 | E32: Perhitungan CO2 dihindari + konversi ke setara pohon dan km | F32: Sri - Backend | G32: Sprint 3 | H32: Medium | I32: Not Started | J32: 46289 | K32: 46291 | L32: =IF(K32="","",K32-TODAY()) | M32: Faktor emisi jaringan perlu sumber resmi
B33: 23 | C33: S3 — Hasil | D33: S3.7 | E33: Review tampilan hasil terhadap mockup Figma | F33: Farrel - Arch & UI | G33: Sprint 3 | H33: Medium | I33: Not Started | J33: 46291 | K33: 46292 | L33: =IF(K33="","",K33-TODAY())
B34: 24 | C34: S4 — Basis Data | D34: S4.1 | E34: Setup SQLite + skrip pembuatan tabel saat aplikasi pertama dijalankan | F34: Sri - Backend | G34: Sprint 4 | H34: High | I34: Not Started | J34: 46293 | K34: 46295 | L34: =IF(K34="","",K34-TODAY()) | M34: Microsoft.Data.Sqlite
B35: 25 | C35: S4 — Basis Data | D35: S4.2 | E35: Repository: simpan, baca, hapus simulasi | F35: Sri - Backend | G35: Sprint 4 | H35: High | I35: Not Started | J35: 46294 | K35: 46296 | L35: =IF(K35="","",K35-TODAY())
B36: 26 | C36: S4 — Basis Data | D36: S4.3 | E36: Halaman Riwayat: tabel skenario + checkbox pilih | F36: Mayra - Frontend | G36: Sprint 4 | H36: High | I36: Not Started | J36: 46294 | K36: 46297 | L36: =IF(K36="","",K36-TODAY())
B37: 27 | C37: S4 — Basis Data | D37: S4.4 | E37: Fitur banding 2-3 skenario berdampingan | F37: Mayra - Frontend | G37: Sprint 4 | H37: Medium | I37: Not Started | J37: 46296 | K37: 46298 | L37: =IF(K37="","",K37-TODAY())
B38: 28 | C38: S4 — Basis Data | D38: S4.5 | E38: Navigasi antar halaman lewat sidebar | F38: Mayra - Frontend | G38: Sprint 4 | H38: High | I38: Not Started | J38: 46293 | K38: 46295 | L38: =IF(K38="","",K38-TODAY()) | M38: Saat ini sidebar belum berfungsi
B39: 29 | C39: S4 — Basis Data | D39: S4.6 | E39: Query uji: agregasi + filter untuk laporan Teknik Basis Data | F39: Sri - Backend | G39: Sprint 4 | H39: Medium | I39: Not Started | J39: 46297 | K39: 46299 | L39: =IF(K39="","",K39-TODAY()) | M39: Tunjukkan SQL asli ke dosen
B40: 30 | C40: S4 — Basis Data | D40: S4.7 | E40: Dokumentasi ERD + penjelasan relasi antar tabel | F40: Farrel - Arch & UI | G40: Sprint 4 | H40: Medium | I40: Not Started | J40: 46297 | K40: 46299 | L40: =IF(K40="","",K40-TODAY())
B41: 31 | C41: S5 — Poles & Demo | D41: S5.1 | E41: Perbaikan bug hasil uji coba semua halaman | F41: Semua | G41: Sprint 5 | H41: High | I41: Not Started | J41: 46300 | K41: 46303 | L41: =IF(K41="","",K41-TODAY())
B42: 32 | C42: S5 — Poles & Demo | D42: S5.2 | E42: Samakan visual semua halaman dengan design system | F42: Farrel - Arch & UI | G42: Sprint 5 | H42: Medium | I42: Not Started | J42: 46300 | K42: 46302 | L42: =IF(K42="","",K42-TODAY())
B43: 33 | C43: S5 — Poles & Demo | D43: S5.3 | E43: Lengkapi README: cara build, screenshot, ERD, sumber data | F43: Farrel - Arch & UI | G43: Sprint 5 | H43: High | I43: Not Started | J43: 46301 | K43: 46303 | L43: =IF(K43="","",K43-TODAY())
B44: 34 | C44: S5 — Poles & Demo | D44: S5.4 | E44: Uji di laptop lain: pastikan jalan tanpa instalasi tambahan | F44: Sri - Backend | G44: Sprint 5 | H44: High | I44: Not Started | J44: 46302 | K44: 46304 | L44: =IF(K44="","",K44-TODAY()) | M44: Risiko terbesar saat demo
B45: 35 | C45: S5 — Poles & Demo | D45: S5.5 | E45: Siapkan slide + skenario demo | F45: Farrel - Arch & UI | G45: Sprint 5 | H45: High | I45: Not Started | J45: 46303 | K45: 46305 | L45: =IF(K45="","",K45-TODAY())
...

Sheet 👥 Team
B2: TEAM ROSTER & RESPONSIBILITIES
B4: Kelompok SunCost — 3 anggota · Junior Project Laboratorium Informatika
B7: # | C7: Role | D7: Nama | E7: NIM | F7: Primary Responsibilities | G7: Status
B8: 1 | C8: Software Architect & UI/UX | D8: Muhammad Farrel Al Ghazy | E8: 24/540589/TK/60022 | F8: Arsitektur aplikasi, design system, mockup Figma, review kode, dokumentasi teknis | G8: Active
B9: 2 | C9: Frontend Developer | D9: Mayravivania Syahda Charisa | E9: 24/538308/TK/59701 | F9: Implementasi halaman WPF, data binding, chart, navigasi antar halaman | G9: Active
B10: 3 | C10: Backend Developer | D10: Sri Wahyuni Arista | E10: 23/521971/TK/57593 | F10: Mesin perhitungan, integrasi Open-Meteo, skema dan akses SQLite | G10: Active
B15: WORKLOAD DISTRIBUTION (otomatis dari Task Tracker)
B16: PIC | C16: Total Tasks | D16: Done | E16: In Progress | F16: Blocked | G16: Not Started | H16: % Complete
B17: Farrel - Arch & UI | C17: =COUNTIF('📋 Task Tracker'!$F$11:$F$212,"Farrel - Arch & UI") | D17: =COUNTIFS('📋 Task Tracker'!$F$11:$F$212,"Farrel - Arch & UI",'📋 Task Tracker'!$I$11:$I$212,"Done") | E17: =COUNTIFS('📋 Task Tracker'!$F$11:$F$212,"Farrel - Arch & UI",'📋 Task Tracker'!$I$11:$I$212,"In Progress") | F17: =COUNTIFS('📋 Task Tracker'!$F$11:$F$212,"Farrel - Arch & UI",'📋 Task Tracker'!$I$11:$I$212,"Blocked") | G17: =COUNTIFS('📋 Task Tracker'!$F$11:$F$212,"Farrel - Arch & UI",'📋 Task Tracker'!$I$11:$I$212,"Not Started") | H17: =IFERROR(D17/C17,0)
B18: Mayra - Frontend | C18: =COUNTIF('📋 Task Tracker'!$F$11:$F$212,"Mayra - Frontend") | D18: =COUNTIFS('📋 Task Tracker'!$F$11:$F$212,"Mayra - Frontend",'📋 Task Tracker'!$I$11:$I$212,"Done") | E18: =COUNTIFS('📋 Task Tracker'!$F$11:$F$212,"Mayra - Frontend",'📋 Task Tracker'!$I$11:$I$212,"In Progress") | F18: =COUNTIFS('📋 Task Tracker'!$F$11:$F$212,"Mayra - Frontend",'📋 Task Tracker'!$I$11:$I$212,"Blocked") | G18: =COUNTIFS('📋 Task Tracker'!$F$11:$F$212,"Mayra - Frontend",'📋 Task Tracker'!$I$11:$I$212,"Not Started") | H18: =IFERROR(D18/C18,0)
B19: Sri - Backend | C19: =COUNTIF('📋 Task Tracker'!$F$11:$F$212,"Sri - Backend") | D19: =COUNTIFS('📋 Task Tracker'!$F$11:$F$212,"Sri - Backend",'📋 Task Tracker'!$I$11:$I$212,"Done") | E19: =COUNTIFS('📋 Task Tracker'!$F$11:$F$212,"Sri - Backend",'📋 Task Tracker'!$I$11:$I$212,"In Progress") | F19: =COUNTIFS('📋 Task Tracker'!$F$11:$F$212,"Sri - Backend",'📋 Task Tracker'!$I$11:$I$212,"Blocked") | G19: =COUNTIFS('📋 Task Tracker'!$F$11:$F$212,"Sri - Backend",'📋 Task Tracker'!$I$11:$I$212,"Not Started") | H19: =IFERROR(D19/C19,0)
B20: Semua | C20: =COUNTIF('📋 Task Tracker'!$F$11:$F$212,"Semua") | D20: =COUNTIFS('📋 Task Tracker'!$F$11:$F$212,"Semua",'📋 Task Tracker'!$I$11:$I$212,"Done") | E20: =COUNTIFS('📋 Task Tracker'!$F$11:$F$212,"Semua",'📋 Task Tracker'!$I$11:$I$212,"In Progress") | F20: =COUNTIFS('📋 Task Tracker'!$F$11:$F$212,"Semua",'📋 Task Tracker'!$I$11:$I$212,"Blocked") | G20: =COUNTIFS('📋 Task Tracker'!$F$11:$F$212,"Semua",'📋 Task Tracker'!$I$11:$I$212,"Not Started") | H20: =IFERROR(D20/C20,0)

Sheet 🔗 Resources
B2: RESOURCES & LINKS
B4: Repo, desain, sumber data, dan referensi perhitungan — jaga tetap terbaru
B6: # | C6: Category | D6: Name | E6: URL / Link | F6: PIC | G6: Notes
B7: 1 | C7: Code Repository | D7: GitHub — 22_SunCost | E7: https://github.com/Yeypayeyy/22_SunCost | F7: Farrel | G7: Repo utama, branch per anggota
B8: 2 | C8: Design | D8: Figma — mockup 5 layar | E8: https://www.figma.com/design/eZ7u3wVkggATG2xYOc4SmW/ | F8: Farrel | G8: Beranda, Input, Hasil x2, Riwayat
B9: 3 | C9: Data Cuaca | D9: Open-Meteo API | E9: https://open-meteo.com/en/docs | F9: Sri | G9: Gratis, tanpa API key
B10: 4 | C10: Referensi | D10: PVGIS — pembanding hasil perhitungan | E10: https://re.jrc.ec.europa.eu/pvg_tools/en/ | F10: Sri | G10: Dipakai untuk validasi S2.8
B11: 5 | C11: Referensi | D11: NREL PVWatts | E11: https://pvwatts.nrel.gov/ | F11: Sri | G11: Rujukan metode perhitungan PV
B12: 6 | C12: Library | D12: Microsoft.Data.Sqlite | E12: https://learn.microsoft.com/dotnet/standard/data/sqlite/ | F12: Sri | G12: Akses basis data lokal
B13: 7 | C13: Tarif | D13: Tarif tenaga listrik PLN | E13: https://web.pln.co.id/pelanggan/tarif-tenaga-listrik | F13: Sri | G13: Perlu diverifikasi tiap triwulan
B14: 8 | C14: Referensi | D14: Faktor emisi jaringan listrik (grid emission factor) | E14: https://gatrik.esdm.go.id/ | F14: Sri | G14: Untuk perhitungan CO2 dihindari
B15: 9 | C15: Dokumentasi | D15: Panduan WPF / .NET 8 | E15: https://learn.microsoft.com/dotnet/desktop/wpf/ | F15: Mayra | G15: Referensi XAML & data binding | I15: <- contoh
B16: 10 | C16: Project Management | D16: Sprint tracker (berkas ini) | E16: SunCost_Sprint_Tracker.xlsx | F16: Farrel | G16: Ada di root repo
